Workbook
Name solver_cvg: 0.0001
Name solver_cvg: 0.0001
Name solver_drv: 1
Name solver_drv: 1
Name solver_eng: 1
Name solver_eng: 1
Name solver_itr: 2147483647
Name solver_itr: 2147483647
Name solver_lin: 2
Name solver_lin: 2
Name solver_mip: 2147483647
Name solver_mip: 2147483647
Name solver_mni: 30
Name solver_mni: 30
Name solver_mrt: 0.075
Name solver_mrt: 0.075
Name solver_msl: 2
Name solver_msl: 2
Name solver_neg: 1
Name solver_neg: 1
Name solver_nod: 2147483647
Name solver_nod: 2147483647
Name solver_num: 2
Name solver_num: 2
Name solver_pre: 0.000001
Name solver_pre: 0.000001
Name solver_rbv: 1
Name solver_rbv: 1
Name solver_rel1: 1
Name solver_rel1: 1
Name solver_rel2: 1
Name solver_rel2: 1
Name solver_rhs1: 1
Name solver_rhs1: 1
Name solver_rhs2: 1
Name solver_rhs2: 1
Name solver_rlx: 2
Name solver_rlx: 1
Name solver_rsd: 0
Name solver_rsd: 0
Name solver_scl: 1
Name solver_scl: 2
Name solver_sho: 2
Name solver_sho: 2
Name solver_ssz: 100
Name solver_ssz: 100
Name solver_tim: 2147483647
Name solver_tim: 2147483647
Name solver_tol: 0.01
Name solver_tol: 0.01
Name solver_typ: 2
Name solver_typ: 2
Name solver_val: 0
Name solver_val: 0
Name solver_ver: 2
Name solver_ver: 2
Name solver_lhs2: Double_Exp_Smoothing_XOM!$L$4
Name solver_lhs1: Double_Exp_Smoothing_XOM!$K$4
Name solver_adj: Double_Exp_Smoothing_XOM!$K$4:$L$4
Name solver_opt: Double_Exp_Smoothing_XOM!$I$4

Sheet XOM_Data
A1: Date | B1: Open | C1: High | D1: Low | E1: Close | F1: Adj Close | G1: Volume | H1: (Xij - Xbarj)^2 | O1: n | P1: =J254 -> 20.928571
A2: 44564 | B2: 61.240002 | C2: 63.599998 | D2: 61.209999 | E2: 63.540001 | F2: 61.115536 | G2: 24282400 | H2: =(E2-$P$4)^2 -> 60.808784 | I2: =COUNT(H2:H21) -> 20 | O2: k | P2: 12
A3: 44565 | B3: 64.129997 | C3: 66.190002 | D3: 64.099998 | E3: 65.93 | F3: 63.414337 | G3: 38584000 | H3: =(E3-$P$4)^2 -> 29.246461 | O3: Month (j) | P3: X(bar)j | Q3: SSEj
A4: 44566 | B4: 66.5 | C4: 67.610001 | D4: 66.480003 | E4: 66.75 | F4: 64.203064 | G4: 34033300 | H4: =(E4-$P$4)^2 -> 21.049741 | O4: January | P4: =AVERAGE(E2:E21) -> 71.338 | Q4: =SUM(H2:H21) -> 220.14031
A5: 44567 | B5: 68 | C5: 68.480003 | D5: 67.07 | E5: 68.32 | F5: 65.71315 | G5: 30668500 | H5: =(E5-$P$4)^2 -> 9.1083222 | O5: February | P5: =AVERAGE(E22:E40) -> 78.886316 | Q5: =SUM(H22:H40) -> 55.191687
A6: 44568 | B6: 68.519997 | C6: 69.18 | D6: 67.980003 | E6: 68.879997 | F6: 66.251778 | G6: 23985400 | H6: =(E6-$P$4)^2 -> 6.0417773 | O6: March | P6: =AVERAGE(E41:E63) -> 82.33826 | Q6: =SUM(H41:H63) -> 179.4641
A7: 44571 | B7: 68.970001 | C7: 69.169998 | D7: 67.949997 | E7: 68.470001 | F7: 65.85743 | G7: 22760300 | H7: =(E7-$P$4)^2 -> 8.2254165 | O7: April | P7: =AVERAGE(E64:E83) -> 85.3355 | Q7: =SUM(H64:H83) -> 81.003031
A8: 44572 | B8: 68.889999 | C8: 71.400002 | D8: 68.580002 | E8: 71.349998 | F8: 68.627533 | G8: 32936100 | H8: =(E8-$P$4)^2 -> 0.0001439592 | O8: May | P8: =AVERAGE(E84:E104) -> 91.012381 | Q8: =SUM(H84:H104) -> 303.68492
A9: 44573 | B9: 71.139999 | C9: 71.809998 | D9: 70.639999 | E9: 71.139999 | F9: 68.425552 | G9: 23045100 | H9: =(E9-$P$4)^2 -> 0.039204277 | O9: June | P9: =AVERAGE(E105:E125) -> 94.013333 | Q9: =SUM(H105:H125) -> 773.27983
A10: 44574 | B10: 71.120003 | C10: 71.580002 | D10: 70.309998 | E10: 70.629997 | F10: 67.935013 | G10: 21043200 | H10: =(E10-$P$4)^2 -> 0.50126782 | O10: July | P10: =AVERAGE(E126:E145) -> 87.4755 | Q10: =SUM(H126:H145) -> 225.20751
A11: 44575 | B11: 70.650002 | C11: 72.150002 | D11: 70.599998 | E11: 71.870003 | F11: 69.127701 | G11: 23012900 | H11: =(E11-$P$4)^2 -> 0.28302751 | O11: August | P11: =AVERAGE(E146:E168) -> 93.799999 | Q11: =SUM(H146:H168) -> 265.50852
A12: 44579 | B12: 72.82 | C12: 73.879997 | D12: 72.010002 | E12: 73.080002 | F12: 70.291527 | G12: 32841200 | H12: =(E12-$P$4)^2 -> 3.034572 | O12: September | P12: =AVERAGE(E169:E189) -> 92.194762 | Q12: =SUM(H169:H189) -> 332.00111
A13: 44580 | B13: 73.75 | C13: 73.860001 | D13: 72.550003 | E13: 73.110001 | F13: 70.320381 | G13: 26431600 | H13: =(E13-$P$4)^2 -> 3.1399886 | O13: October | P13: =AVERAGE(E190:E210) -> 102.35286 | Q13: =SUM(H190:H210) -> 472.0826
A14: 44581 | B14: 72.5 | C14: 74.370003 | D14: 72.260002 | E14: 73.269997 | F14: 70.474281 | G14: 26774600 | H14: =(E14-$P$4)^2 -> 3.7326136 | O14: November | P14: =AVERAGE(E211:E231) -> 112.14905 | Q14: =SUM(H211:H231) -> 54.116559
A15: 44582 | B15: 73.18 | C15: 73.18 | D15: 71.040001 | E15: 72.169998 | F15: 69.416245 | G15: 35995200 | H15: =(E15-$P$4)^2 -> 0.69222117 | O15: December | P15: =AVERAGE(E232:E252) -> 106.92809 | Q15: =SUM(H232:H252) -> 107.4802
A16: 44585 | B16: 70.879997 | C16: 73.080002 | D16: 69.809998 | E16: 72.790001 | F16: 70.012596 | G16: 41507000 | H16: =(E16-$P$4)^2 -> 2.1083078
A17: 44586 | B17: 72.589996 | C17: 75.239998 | D17: 71.389999 | E17: 74.93 | F17: 72.070938 | G17: 39278400 | H17: =(E17-$P$4)^2 -> 12.902466 | P17: Mean | Q17: =AVERAGE(E2:E252) -> 91.652032
A18: 44587 | B18: 75.43 | C18: 76 | D18: 73.489998 | E18: 74.169998 | F18: 71.339935 | G18: 35252400 | H18: =(E18-$P$4)^2 -> 8.0202144 | R18: d.f. | S18: MS
A19: 44588 | B19: 75.459999 | C19: 76.010002 | D19: 73.989998 | E19: 75.120003 | F19: 72.253685 | G19: 29174700 | H19: =(E19-$P$4)^2 -> 14.303549 | P19: SSR | Q19: =12*((P4-Q17)^2 + (P5 - Q17)^2 + (P6 - Q17)^2 + (P7 - Q17)^2 + (P8 - Q17)^2 + (P9 - Q17)^2 + (P10 - Q17)^2 + (P11 - Q17)^2 + (P12 - Q17)^2 + (P13 - Q17)^2 + (P14 - Q17)^2 + (P15 - Q17)^2) -> 17983.18 | R19: =P2-1 -> 11 | S19: =Q19/R19 -> 1634.8346
A20: 44589 | B20: 74.970001 | C20: 75.620003 | D20: 73.949997 | E20: 75.279999 | F20: 72.407585 | G20: 30595700 | H20: =(E20-$P$4)^2 -> 15.539358 | P20: SSE | Q20: =SUM(Q3:Q15) -> 3069.1604 | R20: =P1-P2 -> 8.9285714 | S20: =Q20/R20 -> 343.74596
A21: 44592 | B21: 74.970001 | C21: 76.419998 | D21: 74.269997 | E21: 75.959999 | F21: 73.061638 | G21: 36085500 | H21: =(E21-$P$4)^2 -> 21.362878 | P21: SST | Q21: =Q19+Q20 -> 21052.341 | R21: =P1-1 -> 19.928571
A22: 44593 | B22: 76.449997 | C22: 81.510002 | D22: 76.269997 | E22: 80.830002 | F22: 77.745819 | G22: 61033100 | H22: =(E22-$P$5)^2 -> 3.7779155 | I22: =COUNT(H22:H40) -> 19
A23: 44594 | B23: 80.059998 | C23: 80.809998 | D23: 79.150002 | E23: 80.620003 | F23: 77.543839 | G23: 30299300 | H23: =(E23-$P$5)^2 -> 3.0056708 | R23: F | S23: =S19/S20 -> 4.7559383
A24: 44595 | B24: 80.089996 | C24: 80.309998 | D24: 79.019997 | E24: 79.68 | F24: 76.639694 | G24: 28529400 | H24: =(E24-$P$5)^2 -> 0.62993438 | R24: alpha | S24: 0.005
A25: 44596 | B25: 80.870003 | C25: 82.529999 | D25: 80.870003 | E25: 81.410004 | F25: 78.303696 | G25: 32197500 | H25: =(E25-$P$5)^2 -> 6.3690014 | R25: DF1 | S25: =R19 -> 11
A26: 44599 | B26: 81.139999 | C26: 83.080002 | D26: 80.639999 | E26: 82.389999 | F26: 79.246292 | G26: 34949200 | H26: =(E26-$P$5)^2 -> 12.275795 | R26: DF2 | S26: =R20 -> 8.9285714
A27: 44600 | B27: 82.269997 | C27: 82.5 | D27: 79.919998 | E27: 80.260002 | F27: 77.197563 | G27: 34356300 | H27: =(E27-$P$5)^2 -> 1.8870134 | R27: F critical | S27: =(3.964+3.868)/2 -> 3.916
A28: 44601 | B28: 79.580002 | C28: 80.029999 | D28: 78.709999 | E28: 79 | F28: 76.828011 | G28: 40106100 | H28: =(E28-$P$5)^2 -> 0.012924064
A29: 44602 | B29: 78.720001 | C29: 79.68 | D29: 77.790001 | E29: 78.239998 | F29: 76.088913 | G29: 28527700 | H29: =(E29-$P$5)^2 -> 0.41772689
A30: 44603 | B30: 78.620003 | C30: 80.32 | D30: 78.230003 | E30: 80.209999 | F30: 78.004745 | G30: 42002100 | H30: =(E30-$P$5)^2 -> 1.7521368
A31: 44606 | B31: 79.580002 | C31: 79.839996 | D31: 77.050003 | E31: 78.980003 | F31: 76.808563 | G31: 34652800 | H31: =(E31-$P$5)^2 -> 0.0087772638
A32: 44607 | B32: 76.900002 | C32: 78.190002 | D32: 76.419998 | E32: 77.989998 | F32: 75.845779 | G32: 25075100 | H32: =(E32-$P$5)^2 -> 0.80338586
A33: 44608 | B33: 78.790001 | C33: 79.730003 | D33: 78.040001 | E33: 78.349998 | F33: 76.195877 | G33: 21733800 | H33: =(E33-$P$5)^2 -> 0.28763694
A34: 44609 | B34: 78.480003 | C34: 79.120003 | D34: 77.949997 | E34: 78.230003 | F34: 76.079185 | G34: 23738800 | H34: =(E34-$P$5)^2 -> 0.43074668
A35: 44610 | B35: 77.160004 | C35: 78.169998 | D35: 76.889999 | E35: 77.360001 | F35: 75.233109 | G35: 23394800 | H35: =(E35-$P$5)^2 -> 2.3296373
A36: 44614 | B36: 79.669998 | C36: 79.790001 | D36: 75.309998 | E36: 76.459999 | F36: 74.357849 | G36: 35947800 | H36: =(E36-$P$5)^2 -> 5.8870139
A37: 44615 | B37: 76.459999 | C37: 77.470001 | D37: 76.129997 | E37: 76.769997 | F37: 74.659317 | G37: 25385000 | H37: =(E37-$P$5)^2 -> 4.4788059
A38: 44616 | B38: 79 | C38: 79.029999 | D38: 74.029999 | E38: 75.800003 | F38: 73.716003 | G38: 46199900 | H38: =(E38-$P$5)^2 -> 9.5253276
A39: 44617 | B39: 76.690002 | C39: 77.989998 | D39: 76.260002 | E39: 77.839996 | F39: 75.699898 | G39: 28310300 | H39: =(E39-$P$5)^2 -> 1.0947854
A40: 44620 | B40: 76.510002 | C40: 78.93 | D40: 76.199997 | E40: 78.419998 | F40: 76.263962 | G40: 32204600 | H40: =(E40-$P$5)^2 -> 0.21745243
...

Sheet Double_Exp_Smoothing_XOM
B3: Day | C3: Dt | D3: Ft | E3: St | F3: Gt | G3: Error | H3: abs error | I3: MAD (from 2022) | K3: a | L3: b
B4: 1 | C4: 63.540001 | D4: - | E4: =C4 -> 63.540001 | F4: 0 | I4: {=AVERAGE(ABS(G4:G254))} -> 1.5652233 | K4: 0.98844594 | L4: 0.010715106
B5: 2 | C5: 65.93 | D5: =E4+F4 -> 63.540001 | E5: =$K$4*C5+(1-$K$4)*D5 -> 65.902386 | F5: =$L$4*(E5-E4)+(1-$L$4)*F4 -> 0.025313203 | G5: =D5-C5 -> -2.389999
B6: 3 | C6: 66.75 | D6: =E5+F5 -> 65.927699 | E6: =$K$4*C6+(1-$K$4)*D6 -> 66.740499 | F6: =$L$4*(E6-E5)+(1-$L$4)*F5 -> 0.034022442 | G6: =D6-C6 -> -0.82230099 | I6: MAD (from 2023)
B7: 4 | C7: 68.32 | D7: =E6+F6 -> 66.774522 | E7: =$K$4*C7+(1-$K$4)*D7 -> 68.302143 | F7: =$L$4*(E7-E6)+(1-$L$4)*F6 -> 0.050391072 | G7: =D7-C7 -> -1.5454785 | I7: =AVERAGE(H255:H264) -> 1.7697218
B8: 5 | C8: 68.879997 | D8: =E7+F7 -> 68.352535 | E8: =$K$4*C8+(1-$K$4)*D8 -> 68.873903 | F8: =$L$4*(E8-E7)+(1-$L$4)*F7 -> 0.055977587 | G8: =D8-C8 -> -0.52746248
B9: 6 | C9: 68.470001 | D9: =E8+F8 -> 68.92988 | E9: =$K$4*C9+(1-$K$4)*D9 -> 68.475314 | F9: =$L$4*(E9-E8)+(1-$L$4)*F8 -> 0.051106867 | G9: =D9-C9 -> 0.45987925
B10: 7 | C10: 71.349998 | D10: =E9+F9 -> 68.526421 | E10: =$K$4*C10+(1-$K$4)*D10 -> 71.317374 | F10: =$L$4*(E10-E9)+(1-$L$4)*F9 -> 0.081012222 | G10: =D10-C10 -> -2.8235767
B11: 8 | C11: 71.139999 | D11: =E10+F10 -> 71.398386 | E11: =$K$4*C11+(1-$K$4)*D11 -> 71.142984 | F11: =$L$4*(E11-E10)+(1-$L$4)*F10 -> 0.078275562 | G11: =D11-C11 -> 0.25838744
B12: 9 | C12: 70.629997 | D12: =E11+F11 -> 71.22126 | E12: =$K$4*C12+(1-$K$4)*D12 -> 70.636828 | F12: =$L$4*(E12-E11)+(1-$L$4)*F11 -> 0.072013317 | G12: =D12-C12 -> 0.59126299
B13: 10 | C13: 71.870003 | D13: =E12+F12 -> 70.708842 | E13: =$K$4*C13+(1-$K$4)*D13 -> 71.856587 | F13: =$L$4*(E13-E12)+(1-$L$4)*F12 -> 0.084311527 | G13: =D13-C13 -> -1.1611612
B14: 11 | C14: 73.080002 | D14: =E13+F13 -> 71.940898 | E14: =$K$4*C14+(1-$K$4)*D14 -> 73.066841 | F14: =$L$4*(E14-E13)+(1-$L$4)*F13 -> 0.096376118 | G14: =D14-C14 -> -1.1391036
B15: 12 | C15: 73.110001 | D15: =E14+F14 -> 73.163217 | E15: =$K$4*C15+(1-$K$4)*D15 -> 73.110616 | F15: =$L$4*(E15-E14)+(1-$L$4)*F14 -> 0.095812493 | G15: =D15-C15 -> 0.053215845
B16: 13 | C16: 73.269997 | D16: =E15+F15 -> 73.206428 | E16: =$K$4*C16+(1-$K$4)*D16 -> 73.269263 | F16: =$L$4*(E16-E15)+(1-$L$4)*F15 -> 0.096485768 | G16: =D16-C16 -> -0.063568648
B17: 14 | C17: 72.169998 | D17: =E16+F16 -> 73.365748 | E17: =$K$4*C17+(1-$K$4)*D17 -> 72.183814 | F17: =$L$4*(E17-E16)+(1-$L$4)*F16 -> 0.083821214 | G17: =D17-C17 -> 1.1957503
B18: 15 | C18: 72.790001 | D18: =E17+F17 -> 72.267635 | E18: =$K$4*C18+(1-$K$4)*D18 -> 72.783966 | F18: =$L$4*(E18-E17)+(1-$L$4)*F17 -> 0.089353751 | G18: =D18-C18 -> -0.52236601
B19: 16 | C19: 74.93 | D19: =E18+F18 -> 72.873319 | E19: =$K$4*C19+(1-$K$4)*D19 -> 74.906237 | F19: =$L$4*(E19-E18)+(1-$L$4)*F18 -> 0.11113668 | G19: =D19-C19 -> -2.0566807
... B244: 241 | C244: 105.44 | D244: =E243+F243 -> 106.59174 | E244: =$K$4*C244+(1-$K$4)*D244 -> 105.45331 | F244: =$L$4*(E244-E243)+(1-$L$4)*F243 -> 0.10904994 | G244: =D244-C244 -> 1.1517425
B245: 242 | C245: =XOM_Data!E243 -> 104.7 | D245: =E244+F244 -> 105.56236 | E245: =$K$4*C245+(1-$K$4)*D245 -> 104.70996 | F245: =$L$4*(E245-E244)+(1-$L$4)*F244 -> 0.099916396 | G245: =D245-C245 -> 0.86236224
B246: 243 | C246: =XOM_Data!E244 -> 105.17 | D246: =E245+F245 -> 104.80988 | E246: =$K$4*C246+(1-$K$4)*D246 -> 105.16584 | F246: =$L$4*(E246-E245)+(1-$L$4)*F245 -> 0.10373054 | G246: =D246-C246 -> -0.36012082
B247: 244 | C247: =XOM_Data!E245 -> 106.69 | D247: =E246+F246 -> 105.26957 | E247: =$K$4*C247+(1-$K$4)*D247 -> 106.67359 | F247: =$L$4*(E247-E246)+(1-$L$4)*F246 -> 0.11877479 | G247: =D247-C247 -> -1.4204343
B248: 245 | C248: =XOM_Data!E246 -> 108.06 | D248: =E247+F247 -> 106.79237 | E248: =$K$4*C248+(1-$K$4)*D248 -> 108.04535 | F248: =$L$4*(E248-E247)+(1-$L$4)*F247 -> 0.13220068 | G248: =D248-C248 -> -1.267633
B249: 246 | C249: =XOM_Data!E247 -> 105.88 | D249: =E248+F248 -> 108.17755 | E249: =$K$4*C249+(1-$K$4)*D249 -> 105.90654 | F249: =$L$4*(E249-E248)+(1-$L$4)*F248 -> 0.10786657 | G249: =D249-C249 -> 2.2975554
B250: 247 | C250: =XOM_Data!E248 -> 108.68 | D250: =E249+F249 -> 106.01441 | E250: =$K$4*C250+(1-$K$4)*D250 -> 108.6492 | F250: =$L$4*(E250-E249)+(1-$L$4)*F249 -> 0.13609865 | G250: =D250-C250 -> -2.6655903
B251: 248 | C251: =XOM_Data!E249 -> 110.19 | D251: =E250+F250 -> 108.7853 | E251: =$K$4*C251+(1-$K$4)*D251 -> 110.17377 | F251: =$L$4*(E251-E250)+(1-$L$4)*F250 -> 0.15097627 | G251: =D251-C251 -> -1.4047017
B252: 249 | C252: =XOM_Data!E250 -> 108.38 | D252: =E251+F251 -> 110.32475 | E252: =$K$4*C252+(1-$K$4)*D252 -> 108.40247 | F252: =$L$4*(E252-E251)+(1-$L$4)*F251 -> 0.13037882 | G252: =D252-C252 -> 1.9447513
B253: 250 | C253: =XOM_Data!E251 -> 109.2 | D253: =E252+F252 -> 108.53285 | E253: =$K$4*C253+(1-$K$4)*D253 -> 109.19229 | F253: =$L$4*(E253-E252)+(1-$L$4)*F252 -> 0.13744482 | G253: =D253-C253 -> -0.6671514
A254: last day of 2022 | B254: 251 | C254: =XOM_Data!E252 -> 110.3 | D254: =E253+F253 -> 109.32973 | E254: =$K$4*C254+(1-$K$4)*D254 -> 110.28879 | F254: =$L$4*(E254-E253)+(1-$L$4)*F253 -> 0.14772124 | G254: =D254-C254 -> -0.97026948
A255: first day of 2023 | B255: 252 | C255: 106.51 | D255: =E254+F254 -> 110.43651 | E255: - | F255: - | G255: =D255-C255 -> 3.9265117 | H255: =abs(G255) -> 3.9265117
B256: 253 | C256: 106.82 | D256: =E254+2*F254 -> 110.58423 | E256: - | F256: - | G256: =D256-C256 -> 3.7642349 | H256: =abs(G256) -> 3.7642349
B257: 254 | C257: 109.21 | D257: =$E$254+3*$F$254 -> 110.73196 | E257: - | F257: - | G257: =D257-C257 -> 1.5219572 | H257: =abs(G257) -> 1.5219572
B258: 255 | C258: 110.53 | D258: =$E$254+4*$F$254 -> 110.87968 | E258: - | F258: - | G258: =D258-C258 -> 0.34967841 | H258: =abs(G258) -> 0.34967841
B259: 256 | C259: 108.47 | D259: =$E$254+5*$F$254 -> 111.0274 | E259: - | F259: - | G259: =D259-C259 -> 2.5573977 | H259: =abs(G259) -> 2.5573977
B260: 257 | C260: 110.09 | D260: =$E$254+6*$F$254 -> 111.17512 | E260: - | F260: - | G260: =D260-C260 -> 1.0851239 | H260: =abs(G260) -> 1.0851239
B261: 258 | C261: 111.37 | D261: =$E$254+7*$F$254 -> 111.32284 | E261: - | F261: - | G261: =D261-C261 -> -0.047161864 | H261: =abs(G261) -> 0.047161864
B262: 259 | C262: 113.22 | D262: =$E$254+8*$F$254 -> 111.47056 | E262: - | F262: - | G262: =D262-C262 -> -1.7494386 | H262: =abs(G262) -> 1.7494386
B263: 260 | C263: 113.15 | D263: =$E$254+9*$F$254 -> 111.61828 | E263: - | F263: - | G263: =D263-C263 -> -1.5317184 | H263: =abs(G263) -> 1.5317184
B264: 261 | C264: 112.93 | D264: =$E$254+10*$F$254 -> 111.766 | E264: - | F264: - | G264: =D264-C264 -> -1.1639951 | H264: =abs(G264) -> 1.1639951
